Workbook
Name NativeTimeline_Lead_Date_Final1: #N/A
Name Slicer_Assigned_Agent: #N/A
Name Slicer_City_Final: #N/A
Name Slicer_Company_Segment: #N/A
Name Slicer_Lead_Quarter: #N/A
Name Slicer_Lead_Year: #N/A
Name Slicer_Status_Clean: #N/A

Sheet Dashboard
A1: Operational Performance & Lead Conversion Dashboard Period: Jan 2023–Dec 2024 | Tool: Microsoft Excel Only | P1: Non-Interactive Charts Overview Note: These charts present static data and do not filter with slicer selections.
L3: Metric Benchmarks
A4: Total Leads | C4: Engagement Rate | E4: Conversion Rate | G4: Avg Response Time | I4: Total Target Sales | L4: Metric | M4: Good | N4: Warning | O4: Poor
A5: =Dashboard_Calcs!B2 -> 2550 | C5: =Dashboard_Calcs!B4 -> 0.62901961 | E5: =Dashboard_Calcs!B5 -> 0.14980392 | G5: =Dashboard_Calcs!B6 -> 36 hrs | I5: =Dashboard_Calcs!B9 -> $7,600,859 | L5: Engagement Rate | M5: >=60% | N5: 50%–59.9% | O5: <50%
A6: Cleaned deduplicated leads | C6: Target: ≥60% | E6: Track only | G6: Lower is better | I6: Potential sales value | L6: Avg Response Time | M6: <=6 hrs | N6: >6 to 24 hrs | O6: >24 hrs
A7: =Dashboard_Calcs!C29 -> OK | C7: =Dashboard_Calcs!C30 -> GOOD | E7: =Dashboard_Calcs!C31 -> TRACK | G7: =Dashboard_Calcs!C32 -> POOR | I7: =Dashboard_Calcs!C33 -> OK | L7: Conversion Rate | M7: Compare to dataset average or prior month

Sheet Insight Log
A1: Log | B1: Observation | C1: Source | D1: Insight | E1: Action
A2: 1 | B2: 65.8% of all leads suffer from delayed response times exceeding 24 hours, driving an average response speed of 36 hours. | C2: The Response Speed | D2: Slow follow-ups are cooling down potential pipeline values. The current speed falls significantly short of standard operational benchmarks (<=6 Hours), leading to heavily dropped engagement or lost momentum right at the beginning of the lead funnel. | E2: Establish a strict 6-hour Service Level Agreement (SLA) for inbound leads, prioritizing high-value sales tiers to protect potential pipeline value.
A3: 2 | B3: High-engagement leads are heavily concentrated within specific corporate categories like Private Manufacturing and Regional Finance. | C3: PT_Segment_Conversion & PT_Engagement_Level | D3: Not all leads require equal effort. Our conversion success points heavily toward specific structural segments. Failing to prioritize these segments wastes limited live agent resources on lower-converting business categories. | E3: Deploy automated lead scoring inside the CRM sheet to automatically route and prioritize high-tier segments (Manufacturing/Finance) to agents immediately upon intake.
A4: 3 | B4: Out of 682 New leads, a massive drop-off occurs during the initial contact phase before reaching Qualified status. | C4: PT_Conversion_Funnel | D4: The sales funnel is leaking heavily right at the beginning. Agents are struggling to successfully engage or qualify newly assigned leads, wasting marketing acquisition efforts. | E4: Conduct a audit on early-stage qualification criteria and scripts to identify why fresh leads are stalling or failing to convert to active opportunities.
A5: 4 | B5: Lead assignments are heavily concentrated on a small team of 4 agents, leading to fluctuating monthly conversion rates. | C5: Profiling & Dashboard_Calcs | D5: Operational performance depends on agent capacity. When lead influx peaks, team burnout or slow response times cause conversion rates to fluctuate wildly. | E5: Implement automated round-robin lead allocation and set capacity caps per agent to ensure consistent follow-up quality.
A6: 5 | B6: Leads with "High" engagement levels consistently carry a higher average target sales value (~RM 3,000+) across lifecycle stages. | C6: Pivot_Analysis (PT_Engagement_Level chart/table). | D6: High engagement is a direct indicator of immediate revenue potential. When client accounts interact frequently, they represent deeper pipeline quality and are worth significantly more financially than cold accounts. | E6: Implement an automated priority scoring rule that automatically flags and flags high-engagement leads directly to senior account executives for immediate nurturing.

Sheet Raw_Data
A1: Lead_ID | B1: Client_Name | C1: Company_Segment | D1: City | E1: Assigned_Agent | F1: Lead_Date | G1: Status | H1: Response_Time | I1: Interaction_Count | J1: Target_Sales
A2: CL-1185 | B2: Client_1185 | C2: a regional Financial Institution | D2: Shah Alam | E2: Agent_A | F2: 45272 | G2: Nw | H2: 40.9h | I2: 18 | J2: 2273.47
A3: CL-2445 | B3: Client_2445 | C3: a private Manufacturing enterprise | D3: Penang | E3: Agent_D | F3: 45574 | G3: QUALIFIED | H3: 2.6 days | I3: 37 | J3: 3979.72
A4: CL-2844 | B4: Client_2844 | C4: a major Telecommunications provider | D4: Seremban | E4: Agent_A | F4: 45465 | G4: Qualified | H4: 54.8 | I4: 10 | J4: 3016.59
A5: CL-2472 | B5: client_2472 | C5: a Government Service provider | D5: Kota Kinabalu | E5: Agent_A | F5: 45330 | G5: Contactd | H5: 68.4 | I5: 9 | J5: 4721.15
A6: CL-1033 | B6: Client_1033 | C6: a regional Financial Institution | D6: Johore Bahru | E6: Agent_D | F6: September 5, 2023 | G6: Nw | H6: 28.6 | I6: 37 | J6: 1573.7
A7: CL-1573 | B7: Client_1573 | C7: a private Manufacturing enterprise | D7: shah alam | E7: Agent_B | F7: June 15, 2023 | G7: New | H7: 26.3 hours | I7: 35 | J7: 2406.82
A8: CL-2966 | B8: client_2966 | C8: a private Manufacturing enterprise | D8: Kuala Lumpur | E8: Agent_D | F8: 45200 | G8: Contacted | H8: 35.0h | I8: 19 | J8: 2829.99
A9: CL-2394 | B9: Client_2394 | C9: a private Manufacturing enterprise | D9: Kota Kinabalu | E9: Agent_C | F9: 44997 | G9: Qualified | H9: 64.6 | I9: 29 | J9: 1795.24
A10: CL-2422 | B10: Client_2422 | C10: a regional Financial Institution | D10: Putrajaya | E10: Agent_C | F10: 45390 | G10: lost | H10: 0.6 days | I10: 18 | J10: 1708.81
A11: CL-1014 | B11: Client_1014 | C11: a Government Service provider | D11: seremban | E11: Agent_A | F11: 11-16-2024 | G11: contacted | H11: 46.4h | I11: 12 | J11: 3502.64
A12: CL-0203 | B12: Client_203 | C12: a private Manufacturing enterprise | D12: petaling jaya | E12: Agent_C | F12: 02-23-2023 | G12: Conctacted | H12: 34 | I12: 1 | J12: 1660.75
A13: CL-2903 | B13: Client_2903 | C13: a leading Utility company | D13: Kuala Lumpur | E13: Agent_D | F13: 07.03.2024 | G13: CONTACTED | H13: 17.5h | I13: 48 | J13: 2399.64
A14: CL-2832 | B14: client_2832 | C14: a leading Utility company | D14: Klang | E14: Agent_C | F14: 45195 | G14: Contacted | H14: 61.1h | I14: 26 | J14: 4663.28
A15: CL-1544 | B15: Client_1544 | C15: a regional Financial Institution | D15: cyberjaya | E15: Agent_A | F15: 45535 | G15: New | H15: 31.5 hours | I15: 33 | J15: 1184.3
A16: CL-0857 | B16: Client_857 | C16: a leading Utility company | D16: Klang | E16: Agent_D | F16: 45465 | G16: lost | H16: 1.4 days | I16: 3 interactions | J16: 3250.2
A17: CL-1537 | B17: Client_1537 | C17: a leading Utility company | D17: Subang Jaya | E17: Agent_A | F17: 45282 | G17: Contacted | H17: 2.4 days | I17: 29 | J17: 4161.12
A18: CL-0749 | B18: Client_749 | C18: a private Manufacturing enterprise | D18: Cyberjya | E18: Agent_C | F18: 05-22-2024 | G18: contacted | H18: 6.2h | I18: 9 | J18: 2663.26
A19: CL-0463 | B19: Client_463 | C19: a leading Utility company | D19: Kuching | E19: Agent_D | F19: 45455 | G19: Qualified | H19: 18.3 | I19: 48 | J19: 3262.22
A20: CL-1743 | B20: Client_1743 | C20: a private Manufacturing enterprise | D20: Peneng | E20: Agent_A | F20: 44938 | G20: Qualified | H20: 40.0 hrs | I20: 11 | J20: 4363.7
A21: CL-0010 | B21: Client_010 | C21: a leading Utility company | D21: Putrajaya | E21: Agent_D | F21: 45419 | G21: Qualifeid | H21: 64.7h | I21: 9 | J21: 3789.54
A22: CL-0162 | B22: Client_162 | C22: a regional Financial Institution | D22: PUTRAJAYA | E22: Agent_D | F22: 45573 | G22: Converted | H22: 51.7h | I22: 7 interactions | J22: 4889.42
A23: CL-0946 | B23: Client_946 | C23: a regional Financial Institution | D23: Kuching | E23: Agent_C | F23: 01-18-2024 | G23: LOST | H23: 0.8 days | I23: 8 | J23: 2034.67
A24: CL-0661 | B24: Client_661 | C24: a private Manufacturing enterprise | D24: Klang | E24: Agent_C | F24: 45127 | G24: new | H24: 48.9 | I24: 26 | J24: 2341.95
A25: CL-0650 | B25: CLIENT_650 | C25: a Government Service provider | D25: Kuching | E25: Agent_D | F25: 10-23-2023 | G25: New | H25: 8.5 hrs | I25: 14 | J25: 1635.16
A26: CL-0822 | B26: CLIENT_822 | C26: a regional Financial Institution | D26: seremban | E26: Agent_C | F26: 02-16-2024 | G26: qualified | H26: 0.7 days | I26: 40 | J26: 1372.23
A27: CL-2251 | B27: Client_2251 | C27: a major Telecommunications provider | D27: Petaling Jaya | E27: Agent_B | F27: June 17, 2023 | G27: NEW | H27: 0.1 days | I27: 35 | J27: 1104.89
A28: CL-1572 | B28: Client_1572 | C28: a leading Utility company | D28: Kota Kinabalu | E28: Agent_A | F28: 09.09.2023 | G28: New | H28: 67 | I28: 43 | J28: 3432.11
A29: CL-2773 | B29: Client_2773 | C29: a private Manufacturing enterprise | D29: Klang | E29: Agent_B | F29: 28.09.2024 | G29: Lost | H29: 2.4 hrs | I29: 17 | J29: 4947.52
A30: CL-2897 | B30: Client_2897 | C30: a regional Financial Institution | D30: Kota Kinabalu | E30: Agent_D | F30: 45146 | G30: Contactd | H30: 23.2 hours | I30: 8 | J30: 3321.74
A31: CL-2867 | B31: Client_2867 | C31: a leading Utility company | D31: SHAH ALAM | E31: Agent_C | F31: 45481 | G31: Conctacted | H31: 2.3 days | I31: 22 | J31: 4178.08
A32: CL-2198 | B32: CLIENT_2198 | C32: a major Telecommunications provider | D32: cyberjaya | E32: Agent_A | F32: 13.10.2024 | G32: Converted | H32: 62.5 | I32: 5 | J32: 3857.12
A33: CL-0752 | B33: Client_752 | C33: a private Manufacturing enterprise | D33: Johore Bahru | E33: Agent_A | F33: 02-16-2023 | G33: Conctacted | H33: 0.9 days | I33: 49 | J33: 3943.41
A34: CL-1840 | B34: Client_1840 | C34: a private Manufacturing enterprise | D34: Peneng | E34: Agent_A | F34: 45179 | G34: Conctacted | H34: 45.9 | I34: 15 | J34: 1886.04
A35: CL-1742 | B35: Client_1742 | C35: a Government Service provider | D35: Alor Setar | E35: Agent_B | F35: 45260 | G35: NEW | H35: 2.9 days | I35: 27 | J35: 2905.85
A36: CL-2549 | B36: Client_2549 | C36: a leading Utility company | D36: Subang Jaya | E36: Agent_C | F36: 45463 | G36: NEW | H36: 1.7 | I36: -3 | J36: 3593.33
A37: CL-2909 | B37: Client_2909 | C37: a private Manufacturing enterprise | D37: Kota Kinabalu | E37: Agent_D | F37: 28.04.2023 | G37: Qualified | H37: 40 | I37: 36 | J37: 2647.98
A38: CL-1039 | B38: Client_1039 | C38: a regional Financial Institution | D38: Alor Setar | E38: Agent_B | F38: 45082 | G38: New | H38: 64.5 | I38: N/A | J38: 2595.93
A39: CL-2176 | B39: Client_2176 | C39: a Government Service provider | D39: Kuala Lumpr | E39: Agent_A | F39: 45106 | G39: Lost | H39: 41 | I39: 23 | J39: 4417.33
A40: CL-0820 | B40: Client_820 | C40: a leading Utility company | D40: Subang Jaya | E40: Agent_C | F40: 08.04.2023 | G40: Qualified | H40: 70.2 | I40: 45 | J40: 1643.88
...

Sheet Helper_Column
A1: Lead_ID_Clean | B1: Lead_ID_Fixed | C1: Lead_ID_DupFlag | D1: Keep_Record | E1: Client_Name_Clean | F1: Client_Name_Fixed | G1: Company_Segment | H1: City_Clean | I1: City_Mapping | J1: City_Final | K1: Status_Norm | L1: Status_Clean | M1: Is_Converted | N1: Is_Engaged | O1: Stage_Order | P1: Date_Raw | Q1: Date_NoDots | R1: Date_NoDashes | S1: Date_Converted | T1: Date_Valid | U1: Lead_Date_Final | V1: Lead_Month | W1: Lead_Year | X1: Lead_Quarter | Y1: Lead_Weekday | Z1: Response_Time | AA1: Response_Time_Hours | AB1: Response_Speed_Cat | AC1: Interaction_Count_Final | AD1: Engagement_Level | AE1: Sales_Tier | AF1: Sales_ Check | AG1: Column1 | AH1: Original_Row_No | AI1: Latest_Lead_Date | AJ1: Latest_Row_For_Lead | AK1: REVIEW_AMBIGUOUS
A2: CL-1185 | B2: CL-1185 | C2: FALSE | D2: KEEP | E2: Client_1185 | F2: Client_1185 | G2: A Regional Financial Institution | H2: Shah Alam | I2: Shah Alam | J2: Shah Alam | K2: NW | L2: NEW | M2: =IF(UPPER(TRIM(Table2[[#This Row],[Status_Clean]]))="CONVERTED",1,0) -> 0 | N2: =IF(ISNUMBER(MATCH(UPPER(TRIM(Table2[[#This Row],[Status_Clean]])),{"CONTACTED","QUALIFIED","CONVERTED"},0)),1,0) -> 0 | O2: {=_xlfn.SWITCH(UPPER(TRIM(Table2[[#This Row],[Status_Clean]])),"NEW",1,"CONTACTED",2,"QUALIFIED",3,"CONVERTED",4,"LOST",5,99)} -> 1 | P2: 45272 | Q2: 12/12/2023 | R2: 12/12/2023 | S2: 45272 | T2: PASS | U2: 45272 | V2: December | W2: 2023 | X2: Q4 | Y2: Tuesday | Z2: 40.9h | AA2: 40.9 | AB2: {=_xlfn.LET(_xlpm.x,IFERROR(VALUE(Table2[[#This Row],[Response_Time_Hours]]),""),IF(_xlpm.x="","CHECK",_xlfn.IFS(_xlpm.x<=1,"Immediate",_xlpm.x<=6,"Fast",_xlpm.x<=24,"Moderate",_xlpm.x>24,"Delayed")))} -> Delayed | AC2: 18 | AD2: {=IF(Table2[[#This Row],[Interaction_Count_Final]]="","N/A",_xlfn.IFS(Table2[[#This Row],[Interaction_Count_Final]]<=2,"Low",Table2[[#This Row],[Interaction_Count_Final]]<=5,"Medium",Table2[[#This Row],[Interaction_Count_Final]]>=6,"High",TRUE,"CHECK"))} -> High | AE2: Medium | AF2: TRUE | AG2: TRUE | AH2: 2 | AI2: 45272 | AJ2: TRUE | AK2: {=_xlfn.LET( _xlpm.txt,TRIM(Raw_Data!F2), _xlpm.norm,SUBSTITUTE(SUBSTITUTE(_xlpm.txt,"-","/"),".","/"), _xlpm.p,_xlfn.TEXTSPLIT(_xlpm.norm,"/"), _xlpm.a,VALUE(INDEX(_xlpm.p,1)), _xlpm.b,VALUE(INDEX(_xlpm.p,2)), IF(AND(_xlpm.a<=12,_xlpm.b<=12),"REVIEW_AMBIGUOUS","OK") )} -> #REF!
A3: CL-2445 | B3: CL-2445 | C3: FALSE | D3: KEEP | E3: Client_2445 | F3: Client_2445 | G3: A Private Manufacturing Enterprise | H3: Penang | I3: Penang | J3: Penang | K3: QUALIFIED | L3: QUALIFIED | M3: =IF(UPPER(TRIM(Table2[[#This Row],[Status_Clean]]))="CONVERTED",1,0) -> 0 | N3: =IF(ISNUMBER(MATCH(UPPER(TRIM(Table2[[#This Row],[Status_Clean]])),{"CONTACTED","QUALIFIED","CONVERTED"},0)),1,0) -> 1 | O3: {=_xlfn.SWITCH(UPPER(TRIM(Table2[[#This Row],[Status_Clean]])),"NEW",1,"CONTACTED",2,"QUALIFIED",3,"CONVERTED",4,"LOST",5,99)} -> 3 | P3: 45574 | Q3: 09/10/2024 | R3: 09/10/2024 | S3: 45574 | T3: PASS | U3: 45574 | V3: October | W3: 2024 | X3: Q4 | Y3: Wednesday | Z3: 2.6 days | AA3: 62.4 | AB3: {=_xlfn.LET(_xlpm.x,IFERROR(VALUE(Table2[[#This Row],[Response_Time_Hours]]),""),IF(_xlpm.x="","CHECK",_xlfn.IFS(_xlpm.x<=1,"Immediate",_xlpm.x<=6,"Fast",_xlpm.x<=24,"Moderate",_xlpm.x>24,"Delayed")))} -> Delayed | AC3: 37 | AD3: {=IF(Table2[[#This Row],[Interaction_Count_Final]]="","N/A",_xlfn.IFS(Table2[[#This Row],[Interaction_Count_Final]]<=2,"Low",Table2[[#This Row],[Interaction_Count_Final]]<=5,"Medium",Table2[[#This Row],[Interaction_Count_Final]]>=6,"High",TRUE,"CHECK"))} -> High | AE3: High | AF3: TRUE | AG3: TRUE | AH3: 3 | AI3: 45574 | AJ3: TRUE | AK3: {=_xlfn.LET( _xlpm.txt,TRIM(Raw_Data!F3), _xlpm.norm,SUBSTITUTE(SUBSTITUTE(_xlpm.txt,"-","/"),".","/"), _xlpm.p,_xlfn.TEXTSPLIT(_xlpm.norm,"/"), _xlpm.a,VALUE(INDEX(_xlpm.p,1)), _xlpm.b,VALUE(INDEX(_xlpm.p,2)), IF(AND(_xlpm.a<=12,_xlpm.b<=12),"REVIEW_AMBIGUOUS","OK") )} -> #REF!
A4: CL-2844 | B4: CL-2844 | C4: FALSE | D4: KEEP | E4: Client_2844 | F4: Client_2844 | G4: A Major Telecommunications Provider | H4: Seremban | I4: Seremban | J4: Seremban | K4: QUALIFIED | L4: QUALIFIED | M4: =IF(UPPER(TRIM(Table2[[#This Row],[Status_Clean]]))="CONVERTED",1,0) -> 0 | N4: =IF(ISNUMBER(MATCH(UPPER(TRIM(Table2[[#This Row],[Status_Clean]])),{"CONTACTED","QUALIFIED","CONVERTED"},0)),1,0) -> 1 | O4: {=_xlfn.SWITCH(UPPER(TRIM(Table2[[#This Row],[Status_Clean]])),"NEW",1,"CONTACTED",2,"QUALIFIED",3,"CONVERTED",4,"LOST",5,99)} -> 3 | P4: 45465 | Q4: 22/06/2024 | R4: 22/06/2024 | S4: 45465 | T4: PASS | U4: 45465 | V4: June | W4: 2024 | X4: Q2 | Y4: Saturday | Z4: 54.8 | AA4: 54.8 | AB4: {=_xlfn.LET(_xlpm.x,IFERROR(VALUE(Table2[[#This Row],[Response_Time_Hours]]),""),IF(_xlpm.x="","CHECK",_xlfn.IFS(_xlpm.x<=1,"Immediate",_xlpm.x<=6,"Fast",_xlpm.x<=24,"Moderate",_xlpm.x>24,"Delayed")))} -> Delayed | AC4: 10 | AD4: {=IF(Table2[[#This Row],[Interaction_Count_Final]]="","N/A",_xlfn.IFS(Table2[[#This Row],[Interaction_Count_Final]]<=2,"Low",Table2[[#This Row],[Interaction_Count_Final]]<=5,"Medium",Table2[[#This Row],[Interaction_Count_Final]]>=6,"High",TRUE,"CHECK"))} -> High | AE4: Medium | AF4: TRUE | AG4: TRUE | AH4: 5 | AI4: 45465 | AJ4: TRUE | AK4: {=_xlfn.LET( _xlpm.txt,TRIM(Raw_Data!F4), _xlpm.norm,SUBSTITUTE(SUBSTITUTE(_xlpm.txt,"-","/"),".","/"), _xlpm.p,_xlfn.TEXTSPLIT(_xlpm.norm,"/"), _xlpm.a,VALUE(INDEX(_xlpm.p,1)), _xlpm.b,VALUE(INDEX(_xlpm.p,2)), IF(AND(_xlpm.a<=12,_xlpm.b<=12),"REVIEW_AMBIGUOUS","OK") )} -> #REF!
A5: CL-2472 | B5: CL-2472 | C5: FALSE | D5: KEEP | E5: Client_2472 | F5: Client_2472 | G5: A Government Service Provider | H5: Kota Kinabalu | I5: Kota Kinabalu | J5: Kota Kinabalu | K5: CONTACTD | L5: CONTACTED | M5: =IF(UPPER(TRIM(Table2[[#This Row],[Status_Clean]]))="CONVERTED",1,0) -> 0 | N5: =IF(ISNUMBER(MATCH(UPPER(TRIM(Table2[[#This Row],[Status_Clean]])),{"CONTACTED","QUALIFIED","CONVERTED"},0)),1,0) -> 1 | O5: {=_xlfn.SWITCH(UPPER(TRIM(Table2[[#This Row],[Status_Clean]])),"NEW",1,"CONTACTED",2,"QUALIFIED",3,"CONVERTED",4,"LOST",5,99)} -> 2 | P5: 45330 | Q5: 08/02/2024 | R5: 08/02/2024 | S5: 45330 | T5: PASS | U5: 45330 | V5: February | W5: 2024 | X5: Q1 | Y5: Thursday | Z5: 68.4 | AA5: 68.4 | AB5: {=_xlfn.LET(_xlpm.x,IFERROR(VALUE(Table2[[#This Row],[Response_Time_Hours]]),""),IF(_xlpm.x="","CHECK",_xlfn.IFS(_xlpm.x<=1,"Immediate",_xlpm.x<=6,"Fast",_xlpm.x<=24,"Moderate",_xlpm.x>24,"Delayed")))} -> Delayed | AC5: 9 | AD5: {=IF(Table2[[#This Row],[Interaction_Count_Final]]="","N/A",_xlfn.IFS(Table2[[#This Row],[Interaction_Count_Final]]<=2,"Low",Table2[[#This Row],[Interaction_Count_Final]]<=5,"Medium",Table2[[#This Row],[Interaction_Count_Final]]>=6,"High",TRUE,"CHECK"))} -> High | AE5: High | AF5: TRUE | AG5: TRUE | AH5: 6 | AI5: 45330 | AJ5: TRUE | AK5: {=_xlfn.LET( _xlpm.txt,TRIM(Raw_Data!F5), _xlpm.norm,SUBSTITUTE(SUBSTITUTE(_xlpm.txt,"-","/"),".","/"), _xlpm.p,_xlfn.TEXTSPLIT(_xlpm.norm,"/"), _xlpm.a,VALUE(INDEX(_xlpm.p,1)), _xlpm.b,VALUE(INDEX(_xlpm.p,2)), IF(AND(_xlpm.a<=12,_xlpm.b<=12),"REVIEW_AMBIGUOUS","OK") )} -> #REF!
A6: CL-1033 | B6: CL-1033 | C6: FALSE | D6: KEEP | E6: Client_1033 | F6: Client_1033 | G6: A Regional Financial Institution | H6: Johore Bahru | I6: Johore Bahru | J6: Johor Bahru | K6: NW | L6: NEW | M6: =IF(UPPER(TRIM(Table2[[#This Row],[Status_Clean]]))="CONVERTED",1,0) -> 0 | N6: =IF(ISNUMBER(MATCH(UPPER(TRIM(Table2[[#This Row],[Status_Clean]])),{"CONTACTED","QUALIFIED","CONVERTED"},0)),1,0) -> 0 | O6: {=_xlfn.SWITCH(UPPER(TRIM(Table2[[#This Row],[Status_Clean]])),"NEW",1,"CONTACTED",2,"QUALIFIED",3,"CONVERTED",4,"LOST",5,99)} -> 1 | P6: September 5, 2023 | Q6: September 5 2023 | R6: September 5 2023 | S6: 45174 | T6: PASS | U6: 45174 | V6: September | W6: 2023 | X6: Q3 | Y6: Tuesday | Z6: 28.6 | AA6: 28.6 | AB6: {=_xlfn.LET(_xlpm.x,IFERROR(VALUE(Table2[[#This Row],[Response_Time_Hours]]),""),IF(_xlpm.x="","CHECK",_xlfn.IFS(_xlpm.x<=1,"Immediate",_xlpm.x<=6,"Fast",_xlpm.x<=24,"Moderate",_xlpm.x>24,"Delayed")))} -> Delayed | AC6: 37 | AD6: {=IF(Table2[[#This Row],[Interaction_Count_Final]]="","N/A",_xlfn.IFS(Table2[[#This Row],[Interaction_Count_Final]]<=2,"Low",Table2[[#This Row],[Interaction_Count_Final]]<=5,"Medium",Table2[[#This Row],[Interaction_Count_Final]]>=6,"High",TRUE,"CHECK"))} -> High | AE6: Low | AF6: TRUE | AG6: TRUE | AH6: 9 | AI6: 45174 | AJ6: TRUE | AK6: {=_xlfn.LET( _xlpm.txt,TRIM(Raw_Data!F6), _xlpm.norm,SUBSTITUTE(SUBSTITUTE(_xlpm.txt,"-","/"),".","/"), _xlpm.p,_xlfn.TEXTSPLIT(_xlpm.norm,"/"), _xlpm.a,VALUE(INDEX(_xlpm.p,1)), _xlpm.b,VALUE(INDEX(_xlpm.p,2)), IF(AND(_xlpm.a<=12,_xlpm.b<=12),"REVIEW_AMBIGUOUS","OK") )} -> #REF!
A7: CL-1573 | B7: CL-1573 | C7: FALSE | D7: KEEP | E7: Client_1573 | F7: Client_1573 | G7: A Private Manufacturing Enterprise | H7: Shah Alam | I7: Shah Alam | J7: Shah Alam | K7: NEW | L7: NEW | M7: =IF(UPPER(TRIM(Table2[[#This Row],[Status_Clean]]))="CONVERTED",1,0) -> 0 | N7: =IF(ISNUMBER(MATCH(UPPER(TRIM(Table2[[#This Row],[Status_Clean]])),{"CONTACTED","QUALIFIED","CONVERTED"},0)),1,0) -> 0 | O7: {=_xlfn.SWITCH(UPPER(TRIM(Table2[[#This Row],[Status_Clean]])),"NEW",1,"CONTACTED",2,"QUALIFIED",3,"CONVERTED",4,"LOST",5,99)} -> 1 | P7: June 15, 2023 | Q7: June 15 2023 | R7: June 15 2023 | S7: 45092 | T7: PASS | U7: 45092 | V7: June | W7: 2023 | X7: Q2 | Y7: Thursday | Z7: 26.3 hours | AA7: 26.3 | AB7: {=_xlfn.LET(_xlpm.x,IFERROR(VALUE(Table2[[#This Row],[Response_Time_Hours]]),""),IF(_xlpm.x="","CHECK",_xlfn.IFS(_xlpm.x<=1,"Immediate",_xlpm.x<=6,"Fast",_xlpm.x<=24,"Moderate",_xlpm.x>24,"Delayed")))} -> Delayed | AC7: 35 | AD7: {=IF(Table2[[#This Row],[Interaction_Count_Final]]="","N/A",_xlfn.IFS(Table2[[#This Row],[Interaction_Count_Final]]<=2,"Low",Table2[[#This Row],[Interaction_Count_Final]]<=5,"Medium",Table2[[#This Row],[Interaction_Count_Final]]>=6,"High",TRUE,"CHECK"))} -> High | AE7: Medium | AF7: TRUE | AG7: TRUE | AH7: 10 | AI7: 45092 | AJ7: TRUE | AK7: {=_xlfn.LET( _xlpm.txt,TRIM(Raw_Data!F7), _xlpm.norm,SUBSTITUTE(SUBSTITUTE(_xlpm.txt,"-","/"),".","/"), _xlpm.p,_xlfn.TEXTSPLIT(_xlpm.norm,"/"), _xlpm.a,VALUE(INDEX(_xlpm.p,1)), _xlpm.b,VALUE(INDEX(_xlpm.p,2)), IF(AND(_xlpm.a<=12,_xlpm.b<=12),"REVIEW_AMBIGUOUS","OK") )} -> #REF!
A8: CL-2966 | B8: CL-2966 | C8: FALSE | D8: KEEP | E8: Client_2966 | F8: Client_2966 | G8: A Private Manufacturing Enterprise | H8: Kuala Lumpur | I8: Kuala Lumpur | J8: Kuala Lumpur | K8: CONTACTED | L8: CONTACTED | M8: =IF(UPPER(TRIM(Table2[[#This Row],[Status_Clean]]))="CONVERTED",1,0) -> 0 | N8: =IF(ISNUMBER(MATCH(UPPER(TRIM(Table2[[#This Row],[Status_Clean]])),{"CONTACTED","QUALIFIED","CONVERTED"},0)),1,0) -> 1 | O8: {=_xlfn.SWITCH(UPPER(TRIM(Table2[[#This Row],[Status_Clean]])),"NEW",1,"CONTACTED",2,"QUALIFIED",3,"CONVERTED",4,"LOST",5,99)} -> 2 | P8: 45200 | Q8: 01/10/2023 | R8: 01/10/2023 | S8: 45200 | T8: PASS | U8: 45200 | V8: October | W8: 2023 | X8: Q4 | Y8: Sunday | Z8: 35.0h | AA8: 35 | AB8: {=_xlfn.LET(_xlpm.x,IFERROR(VALUE(Table2[[#This Row],[Response_Time_Hours]]),""),IF(_xlpm.x="","CHECK",_xlfn.IFS(_xlpm.x<=1,"Immediate",_xlpm.x<=6,"Fast",_xlpm.x<=24,"Moderate",_xlpm.x>24,"Delayed")))} -> Delayed | AC8: 19 | AD8: {=IF(Table2[[#This Row],[Interaction_Count_Final]]="","N/A",_xlfn.IFS(Table2[[#This Row],[Interaction_Count_Final]]<=2,"Low",Table2[[#This Row],[Interaction_Count_Final]]<=5,"Medium",Table2[[#This Row],[Interaction_Count_Final]]>=6,"High",TRUE,"CHECK"))} -> High | AE8: Medium | AF8: TRUE | AG8: TRUE | AH8: 11 | AI8: 45200 | AJ8: TRUE | AK8: {=_xlfn.LET( _xlpm.txt,TRIM(Raw_Data!F8), _xlpm.norm,SUBSTITUTE(SUBSTITUTE(_xlpm.txt,"-","/"),".","/"), _xlpm.p,_xlfn.TEXTSPLIT(_xlpm.norm,"/"), _xlpm.a,VALUE(INDEX(_xlpm.p,1)), _xlpm.b,VALUE(INDEX(_xlpm.p,2)), IF(AND(_xlpm.a<=12,_xlpm.b<=12),"REVIEW_AMBIGUOUS","OK") )} -> #REF!
A9: CL-2394 | B9: CL-2394 | C9: FALSE | D9: KEEP | E9: Client_2394 | F9: Client_2394 | G9: A Private Manufacturing Enterprise | H9: Kota Kinabalu | I9: Kota Kinabalu | J9: Kota Kinabalu | K9: QUALIFIED | L9: QUALIFIED | M9: =IF(UPPER(TRIM(Table2[[#This Row],[Status_Clean]]))="CONVERTED",1,0) -> 0 | N9: =IF(ISNUMBER(MATCH(UPPER(TRIM(Table2[[#This Row],[Status_Clean]])),{"CONTACTED","QUALIFIED","CONVERTED"},0)),1,0) -> 1 | O9: {=_xlfn.SWITCH(UPPER(TRIM(Table2[[#This Row],[Status_Clean]])),"NEW",1,"CONTACTED",2,"QUALIFIED",3,"CONVERTED",4,"LOST",5,99)} -> 3 | P9: 44997 | Q9: 12/03/2023 | R9: 12/03/2023 | S9: 44997 | T9: PASS | U9: 44997 | V9: March | W9: 2023 | X9: Q1 | Y9: Sunday | Z9: 64.6 | AA9: 64.6 | AB9: {=_xlfn.LET(_xlpm.x,IFERROR(VALUE(Table2[[#This Row],[Response_Time_Hours]]),""),IF(_xlpm.x="","CHECK",_xlfn.IFS(_xlpm.x<=1,"Immediate",_xlpm.x<=6,"Fast",_xlpm.x<=24,"Moderate",_xlpm.x>24,"Delayed")))} -> Delayed | AC9: 29 | AD9: {=IF(Table2[[#This Row],[Interaction_Count_Final]]="","N/A",_xlfn.IFS(Table2[[#This Row],[Interaction_Count_Final]]<=2,"Low",Table2[[#This Row],[Interaction_Count_Final]]<=5,"Medium",Table2[[#This Row],[Interaction_Count_Final]]>=6,"High",TRUE,"CHECK"))} -> High | AE9: Low | AF9: TRUE | AG9: TRUE | AH9: 12 | AI9: 44997 | AJ9: TRUE | AK9: {=_xlfn.LET( _xlpm.txt,TRIM(Raw_Data!F9), _xlpm.norm,SUBSTITUTE(SUBSTITUTE(_xlpm.txt,"-","/"),".","/"), _xlpm.p,_xlfn.TEXTSPLIT(_xlpm.norm,"/"), _xlpm.a,VALUE(INDEX(_xlpm.p,1)), _xlpm.b,VALUE(INDEX(_xlpm.p,2)), IF(AND(_xlpm.a<=12,_xlpm.b<=12),"REVIEW_AMBIGUOUS","OK") )} -> #REF!
A10: CL-2422 | B10: CL-2422 | C10: FALSE | D10: KEEP | E10: Client_2422 | F10: Client_2422 | G10: A Regional Financial Institution | H10: Putrajaya | I10: Putrajaya | J10: Putrajaya | K10: LOST | L10: LOST | M10: =IF(UPPER(TRIM(Table2[[#This Row],[Status_Clean]]))="CONVERTED",1,0) -> 0 | N10: =IF(ISNUMBER(MATCH(UPPER(TRIM(Table2[[#This Row],[Status_Clean]])),{"CONTACTED","QUALIFIED","CONVERTED"},0)),1,0) -> 0 | O10: {=_xlfn.SWITCH(UPPER(TRIM(Table2[[#This Row],[Status_Clean]])),"NEW",1,"CONTACTED",2,"QUALIFIED",3,"CONVERTED",4,"LOST",5,99)} -> 5 | P10: 45390 | Q10: 08/04/2024 | R10: 08/04/2024 | S10: 45390 | T10: PASS | U10: 45390 | V10: April | W10: 2024 | X10: Q2 | Y10: Monday | Z10: 0.6 days | AA10: 14.4 | AB10: {=_xlfn.LET(_xlpm.x,IFERROR(VALUE(Table2[[#This Row],[Response_Time_Hours]]),""),IF(_xlpm.x="","CHECK",_xlfn.IFS(_xlpm.x<=1,"Immediate",_xlpm.x<=6,"Fast",_xlpm.x<=24,"Moderate",_xlpm.x>24,"Delayed")))} -> Moderate | AC10: 18 | AD10: {=IF(Table2[[#This Row],[Interaction_Count_Final]]="","N/A",_xlfn.IFS(Table2[[#This Row],[Interaction_Count_Final]]<=2,"Low",Table2[[#This Row],[Interaction_Count_Final]]<=5,"Medium",Table2[[#This Row],[Interaction_Count_Final]]>=6,"High",TRUE,"CHECK"))} -> High | AE10: Low | AF10: TRUE | AG10: TRUE | AH10: 14 | AI10: 45390 | AJ10: TRUE | AK10: {=_xlfn.LET( _xlpm.txt,TRIM(Raw_Data!F10), _xlpm.norm,SUBSTITUTE(SUBSTITUTE(_xlpm.txt,"-","/"),".","/"), _xlpm.p,_xlfn.TEXTSPLIT(_xlpm.norm,"/"), _xlpm.a,VALUE(INDEX(_xlpm.p,1)), _xlpm.b,VALUE(INDEX(_xlpm.p,2)), IF(AND(_xlpm.a<=12,_xlpm.b<=12),"REVIEW_AMBIGUOUS","OK") )} -> #REF!
A11: CL-1014 | B11: CL-1014 | C11: FALSE | D11: KEEP | E11: Client_1014 | F11: Client_1014 | G11: A Government Service Provider | H11: Seremban | I11: Seremban | J11: Seremban | K11: CONTACTED | L11: CONTACTED | M11: =IF(UPPER(TRIM(Table2[[#This Row],[Status_Clean]]))="CONVERTED",1,0) -> 0 | N11: =IF(ISNUMBER(MATCH(UPPER(TRIM(Table2[[#This Row],[Status_Clean]])),{"CONTACTED","QUALIFIED","CONVERTED"},0)),1,0) -> 1 | O11: {=_xlfn.SWITCH(UPPER(TRIM(Table2[[#This Row],[Status_Clean]])),"NEW",1,"CONTACTED",2,"QUALIFIED",3,"CONVERTED",4,"LOST",5,99)} -> 2 | P11: 11-16-2024 | Q11: 11/16/2024 | R11: 11/16/2024 | S11: 45612 | T11: PASS | U11: 45612 | V11: November | W11: 2024 | X11: Q4 | Y11: Saturday | Z11: 46.4h | AA11: 46.4 | AB11: {=_xlfn.LET(_xlpm.x,IFERROR(VALUE(Table2[[#This Row],[Response_Time_Hours]]),""),IF(_xlpm.x="","CHECK",_xlfn.IFS(_xlpm.x<=1,"Immediate",_xlpm.x<=6,"Fast",_xlpm.x<=24,"Moderate",_xlpm.x>24,"Delayed")))} -> Delayed | AC11: 12 | AD11: {=IF(Table2[[#This Row],[Interaction_Count_Final]]="","N/A",_xlfn.IFS(Table2[[#This Row],[Interaction_Count_Final]]<=2,"Low",Table2[[#This Row],[Interaction_Count_Final]]<=5,"Medium",Table2[[#This Row],[Interaction_Count_Final]]>=6,"High",TRUE,"CHECK"))} -> High | AE11: Medium | AF11: TRUE | AG11: TRUE | AH11: 15 | AI11: 45612 | AJ11: TRUE | AK11: {=_xlfn.LET( _xlpm.txt,TRIM(Raw_Data!F11), _xlpm.norm,SUBSTITUTE(SUBSTITUTE(_xlpm.txt,"-","/"),".","/"), _xlpm.p,_xlfn.TEXTSPLIT(_xlpm.norm,"/"), _xlpm.a,VALUE(INDEX(_xlpm.p,1)), _xlpm.b,VALUE(INDEX(_xlpm.p,2)), IF(AND(_xlpm.a<=12,_xlpm.b<=12),"REVIEW_AMBIGUOUS","OK") )} -> OK
A12: CL-0203 | B12: CL-0203 | C12: FALSE | D12: KEEP | E12: Client_203 | F12: Client_203 | G12: A Private Manufacturing Enterprise | H12: Petaling Jaya | I12: Petaling Jaya | J12: Petaling Jaya | K12: CONCTACTED | L12: CONTACTED | M12: =IF(UPPER(TRIM(Table2[[#This Row],[Status_Clean]]))="CONVERTED",1,0) -> 0 | N12: =IF(ISNUMBER(MATCH(UPPER(TRIM(Table2[[#This Row],[Status_Clean]])),{"CONTACTED","QUALIFIED","CONVERTED"},0)),1,0) -> 1 | O12: {=_xlfn.SWITCH(UPPER(TRIM(Table2[[#This Row],[Status_Clean]])),"NEW",1,"CONTACTED",2,"QUALIFIED",3,"CONVERTED",4,"LOST",5,99)} -> 2 | P12: 02-23-2023 | Q12: 02/23/2023 | R12: 02/23/2023 | S12: 44980 | T12: PASS | U12: 44980 | V12: February | W12: 2023 | X12: Q1 | Y12: Thursday | Z12: 34 | AA12: 34 | AB12: {=_xlfn.LET(_xlpm.x,IFERROR(VALUE(Table2[[#This Row],[Response_Time_Hours]]),""),IF(_xlpm.x="","CHECK",_xlfn.IFS(_xlpm.x<=1,"Immediate",_xlpm.x<=6,"Fast",_xlpm.x<=24,"Moderate",_xlpm.x>24,"Delayed")))} -> Delayed | AC12: 1 | AD12: {=IF(Table2[[#This Row],[Interaction_Count_Final]]="","N/A",_xlfn.IFS(Table2[[#This Row],[Interaction_Count_Final]]<=2,"Low",Table2[[#This Row],[Interaction_Count_Final]]<=5,"Medium",Table2[[#This Row],[Interaction_Count_Final]]>=6,"High",TRUE,"CHECK"))} -> Low | AE12: Low | AF12: TRUE | AG12: TRUE | AH12: 16 | AI12: 44980 | AJ12: TRUE | AK12: {=_xlfn.LET( _xlpm.txt,TRIM(Raw_Data!F12), _xlpm.norm,SUBSTITUTE(SUBSTITUTE(_xlpm.txt,"-","/"),".","/"), _xlpm.p,_xlfn.TEXTSPLIT(_xlpm.norm,"/"), _xlpm.a,VALUE(INDEX(_xlpm.p,1)), _xlpm.b,VALUE(INDEX(_xlpm.p,2)), IF(AND(_xlpm.a<=12,_xlpm.b<=12),"REVIEW_AMBIGUOUS","OK") )} -> OK
A13: CL-2903 | B13: CL-2903 | C13: FALSE | D13: KEEP | E13: Client_2903 | F13: Client_2903 | G13: A Leading Utility Company | H13: Kuala Lumpur | I13: Kuala Lumpur | J13: Kuala Lumpur | K13: CONTACTED | L13: CONTACTED | M13: =IF(UPPER(TRIM(Table2[[#This Row],[Status_Clean]]))="CONVERTED",1,0) -> 0 | N13: =IF(ISNUMBER(MATCH(UPPER(TRIM(Table2[[#This Row],[Status_Clean]])),{"CONTACTED","QUALIFIED","CONVERTED"},0)),1,0) -> 1 | O13: {=_xlfn.SWITCH(UPPER(TRIM(Table2[[#This Row],[Status_Clean]])),"NEW",1,"CONTACTED",2,"QUALIFIED",3,"CONVERTED",4,"LOST",5,99)} -> 2 | P13: 07.03.2024 | Q13: 07/03/2024 | R13: 07/03/2024 | S13: 45476 | T13: PASS | U13: 45476 | V13: July | W13: 2024 | X13: Q3 | Y13: Wednesday | Z13: 17.5h | AA13: 17.5 | AB13: {=_xlfn.LET(_xlpm.x,IFERROR(VALUE(Table2[[#This Row],[Response_Time_Hours]]),""),IF(_xlpm.x="","CHECK",_xlfn.IFS(_xlpm.x<=1,"Immediate",_xlpm.x<=6,"Fast",_xlpm.x<=24,"Moderate",_xlpm.x>24,"Delayed")))} -> Moderate | AC13: 48 | AD13: {=IF(Table2[[#This Row],[Interaction_Count_Final]]="","N/A",_xlfn.IFS(Table2[[#This Row],[Interaction_Count_Final]]<=2,"Low",Table2[[#This Row],[Interaction_Count_Final]]<=5,"Medium",Table2[[#This Row],[Interaction_Count_Final]]>=6,"High",TRUE,"CHECK"))} -> High | AE13: Medium | AF13: TRUE | AG13: TRUE | AH13: 18 | AI13: 45476 | AJ13: TRUE | AK13: {=_xlfn.LET( _xlpm.txt,TRIM(Raw_Data!F13), _xlpm.norm,SUBSTITUTE(SUBSTITUTE(_xlpm.txt,"-","/"),".","/"), _xlpm.p,_xlfn.TEXTSPLIT(_xlpm.norm,"/"), _xlpm.a,VALUE(INDEX(_xlpm.p,1)), _xlpm.b,VALUE(INDEX(_xlpm.p,2)), IF(AND(_xlpm.a<=12,_xlpm.b<=12),"REVIEW_AMBIGUOUS","OK") )} -> REVIEW_AMBIGUOUS
A14: CL-2832 | B14: CL-2832 | C14: FALSE | D14: KEEP | E14: Client_2832 | F14: Client_2832 | G14: A Leading Utility Company | H14: Klang | I14: Klang | J14: Klang | K14: CONTACTED | L14: CONTACTED | M14: =IF(UPPER(TRIM(Table2[[#This Row],[Status_Clean]]))="CONVERTED",1,0) -> 0 | N14: =IF(ISNUMBER(MATCH(UPPER(TRIM(Table2[[#This Row],[Status_Clean]])),{"CONTACTED","QUALIFIED","CONVERTED"},0)),1,0) -> 1 | O14: {=_xlfn.SWITCH(UPPER(TRIM(Table2[[#This Row],[Status_Clean]])),"NEW",1,"CONTACTED",2,"QUALIFIED",3,"CONVERTED",4,"LOST",5,99)} -> 2 | P14: 45195 | Q14: 26/09/2023 | R14: 26/09/2023 | S14: 45195 | T14: PASS | U14: 45195 | V14: September | W14: 2023 | X14: Q3 | Y14: Tuesday | Z14: 61.1h | AA14: 61.1 | AB14: {=_xlfn.LET(_xlpm.x,IFERROR(VALUE(Table2[[#This Row],[Response_Time_Hours]]),""),IF(_xlpm.x="","CHECK",_xlfn.IFS(_xlpm.x<=1,"Immediate",_xlpm.x<=6,"Fast",_xlpm.x<=24,"Moderate",_xlpm.x>24,"Delayed")))} -> Delayed | AC14: 26 | AD14: {=IF(Table2[[#This Row],[Interaction_Count_Final]]="","N/A",_xlfn.IFS(Table2[[#This Row],[Interaction_Count_Final]]<=2,"Low",Table2[[#This Row],[Interaction_Count_Final]]<=5,"Medium",Table2[[#This Row],[Interaction_Count_Final]]>=6,"High",TRUE,"CHECK"))} -> High | AE14: High | AF14: TRUE | AG14: TRUE | AH14: 20 | AI14: 45195 | AJ14: TRUE | AK14: {=_xlfn.LET( _xlpm.txt,TRIM(Raw_Data!F14), _xlpm.norm,SUBSTITUTE(SUBSTITUTE(_xlpm.txt,"-","/"),".","/"), _xlpm.p,_xlfn.TEXTSPLIT(_xlpm.norm,"/"), _xlpm.a,VALUE(INDEX(_xlpm.p,1)), _xlpm.b,VALUE(INDEX(_xlpm.p,2)), IF(AND(_xlpm.a<=12,_xlpm.b<=12),"REVIEW_AMBIGUOUS","OK") )} -> #REF!
A15: CL-1544 | B15: CL-1544 | C15: FALSE | D15: KEEP | E15: Client_1544 | F15: Client_1544 | G15: A Regional Financial Institution | H15: Cyberjaya | I15: Cyberjaya | J15: CyberJaya | K15: NEW | L15: NEW | M15: =IF(UPPER(TRIM(Table2[[#This Row],[Status_Clean]]))="CONVERTED",1,0) -> 0 | N15: =IF(ISNUMBER(MATCH(UPPER(TRIM(Table2[[#This Row],[Status_Clean]])),{"CONTACTED","QUALIFIED","CONVERTED"},0)),1,0) -> 0 | O15: {=_xlfn.SWITCH(UPPER(TRIM(Table2[[#This Row],[Status_Clean]])),"NEW",1,"CONTACTED",2,"QUALIFIED",3,"CONVERTED",4,"LOST",5,99)} -> 1 | P15: 45535 | Q15: 31/08/2024 | R15: 31/08/2024 | S15: 45535 | T15: PASS | U15: 45535 | V15: August | W15: 2024 | X15: Q3 | Y15: Saturday | Z15: 31.5 hours | AA15: 31.5 | AB15: {=_xlfn.LET(_xlpm.x,IFERROR(VALUE(Table2[[#This Row],[Response_Time_Hours]]),""),IF(_xlpm.x="","CHECK",_xlfn.IFS(_xlpm.x<=1,"Immediate",_xlpm.x<=6,"Fast",_xlpm.x<=24,"Moderate",_xlpm.x>24,"Delayed")))} -> Delayed | AC15: 33 | AD15: {=IF(Table2[[#This Row],[Interaction_Count_Final]]="","N/A",_xlfn.IFS(Table2[[#This Row],[Interaction_Count_Final]]<=2,"Low",Table2[[#This Row],[Interaction_Count_Final]]<=5,"Medium",Table2[[#This Row],[Interaction_Count_Final]]>=6,"High",TRUE,"CHECK"))} -> High | AE15: Low | AF15: TRUE | AG15: TRUE | AH15: 21 | AI15: 45535 | AJ15: TRUE | AK15: {=_xlfn.LET( _xlpm.txt,TRIM(Raw_Data!F15), _xlpm.norm,SUBSTITUTE(SUBSTITUTE(_xlpm.txt,"-","/"),".","/"), _xlpm.p,_xlfn.TEXTSPLIT(_xlpm.norm,"/"), _xlpm.a,VALUE(INDEX(_xlpm.p,1)), _xlpm.b,VALUE(INDEX(_xlpm.p,2)), IF(AND(_xlpm.a<=12,_xlpm.b<=12),"REVIEW_AMBIGUOUS","OK") )} -> #REF!
A16: CL-0857 | B16: CL-0857 | C16: FALSE | D16: KEEP | E16: Client_857 | F16: Client_857 | G16: A Leading Utility Company | H16: Klang | I16: Klang | J16: Klang | K16: LOST | L16: LOST | M16: =IF(UPPER(TRIM(Table2[[#This Row],[Status_Clean]]))="CONVERTED",1,0) -> 0 | N16: =IF(ISNUMBER(MATCH(UPPER(TRIM(Table2[[#This Row],[Status_Clean]])),{"CONTACTED","QUALIFIED","CONVERTED"},0)),1,0) -> 0 | O16: {=_xlfn.SWITCH(UPPER(TRIM(Table2[[#This Row],[Status_Clean]])),"NEW",1,"CONTACTED",2,"QUALIFIED",3,"CONVERTED",4,"LOST",5,99)} -> 5 | P16: 45465 | Q16: 22/06/2024 | R16: 22/06/2024 | S16: 45465 | T16: PASS | U16: 45465 | V16: June | W16: 2024 | X16: Q2 | Y16: Saturday | Z16: 1.4 days | AA16: 33.6 | AB16: {=_xlfn.LET(_xlpm.x,IFERROR(VALUE(Table2[[#This Row],[Response_Time_Hours]]),""),IF(_xlpm.x="","CHECK",_xlfn.IFS(_xlpm.x<=1,"Immediate",_xlpm.x<=6,"Fast",_xlpm.x<=24,"Moderate",_xlpm.x>24,"Delayed")))} -> Delayed | AC16: 3 | AD16: {=IF(Table2[[#This Row],[Interaction_Count_Final]]="","N/A",_xlfn.IFS(Table2[[#This Row],[Interaction_Count_Final]]<=2,"Low",Table2[[#This Row],[Interaction_Count_Final]]<=5,"Medium",Table2[[#This Row],[Interaction_Count_Final]]>=6,"High",TRUE,"CHECK"))} -> Medium | AE16: Medium | AF16: TRUE | AG16: TRUE | AH16: 22 | AI16: 45465 | AJ16: TRUE | AK16: {=_xlfn.LET( _xlpm.txt,TRIM(Raw_Data!F16), _xlpm.norm,SUBSTITUTE(SUBSTITUTE(_xlpm.txt,"-","/"),".","/"), _xlpm.p,_xlfn.TEXTSPLIT(_xlpm.norm,"/"), _xlpm.a,VALUE(INDEX(_xlpm.p,1)), _xlpm.b,VALUE(INDEX(_xlpm.p,2)), IF(AND(_xlpm.a<=12,_xlpm.b<=12),"REVIEW_AMBIGUOUS","OK") )} -> #REF!
A17: CL-1537 | B17: CL-1537 | C17: FALSE | D17: KEEP | E17: Client_1537 | F17: Client_1537 | G17: A Leading Utility Company | H17: Subang Jaya | I17: Subang Jaya | J17: Subang Jaya | K17: CONTACTED | L17: CONTACTED | M17: =IF(UPPER(TRIM(Table2[[#This Row],[Status_Clean]]))="CONVERTED",1,0) -> 0 | N17: =IF(ISNUMBER(MATCH(UPPER(TRIM(Table2[[#This Row],[Status_Clean]])),{"CONTACTED","QUALIFIED","CONVERTED"},0)),1,0) -> 1 | O17: {=_xlfn.SWITCH(UPPER(TRIM(Table2[[#This Row],[Status_Clean]])),"NEW",1,"CONTACTED",2,"QUALIFIED",3,"CONVERTED",4,"LOST",5,99)} -> 2 | P17: 45282 | Q17: 22/12/2023 | R17: 22/12/2023 | S17: 45282 | T17: PASS | U17: 45282 | V17: December | W17: 2023 | X17: Q4 | Y17: Friday | Z17: 2.4 days | AA17: 57.6 | AB17: {=_xlfn.LET(_xlpm.x,IFERROR(VALUE(Table2[[#This Row],[Response_Time_Hours]]),""),IF(_xlpm.x="","CHECK",_xlfn.IFS(_xlpm.x<=1,"Immediate",_xlpm.x<=6,"Fast",_xlpm.x<=24,"Moderate",_xlpm.x>24,"Delayed")))} -> Delayed | AC17: 29 | AD17: {=IF(Table2[[#This Row],[Interaction_Count_Final]]="","N/A",_xlfn.IFS(Table2[[#This Row],[Interaction_Count_Final]]<=2,"Low",Table2[[#This Row],[Interaction_Count_Final]]<=5,"Medium",Table2[[#This Row],[Interaction_Count_Final]]>=6,"High",TRUE,"CHECK"))} -> High | AE17: High | AF17: TRUE | AG17: TRUE | AH17: 23 | AI17: 45282 | AJ17: TRUE | AK17: {=_xlfn.LET( _xlpm.txt,TRIM(Raw_Data!F17), _xlpm.norm,SUBSTITUTE(SUBSTITUTE(_xlpm.txt,"-","/"),".","/"), _xlpm.p,_xlfn.TEXTSPLIT(_xlpm.norm,"/"), _xlpm.a,VALUE(INDEX(_xlpm.p,1)), _xlpm.b,VALUE(INDEX(_xlpm.p,2)), IF(AND(_xlpm.a<=12,_xlpm.b<=12),"REVIEW_AMBIGUOUS","OK") )} -> #REF!
A18: CL-0749 | B18: CL-0749 | C18: FALSE | D18: KEEP | E18: Client_749 | F18: Client_749 | G18: A Private Manufacturing Enterprise | H18: Cyberjya | I18: Cyberjya | J18: CyberJaya | K18: CONTACTED | L18: CONTACTED | M18: =IF(UPPER(TRIM(Table2[[#This Row],[Status_Clean]]))="CONVERTED",1,0) -> 0 | N18: =IF(ISNUMBER(MATCH(UPPER(TRIM(Table2[[#This Row],[Status_Clean]])),{"CONTACTED","QUALIFIED","CONVERTED"},0)),1,0) -> 1 | O18: {=_xlfn.SWITCH(UPPER(TRIM(Table2[[#This Row],[Status_Clean]])),"NEW",1,"CONTACTED",2,"QUALIFIED",3,"CONVERTED",4,"LOST",5,99)} -> 2 | P18: 05-22-2024 | Q18: 05/22/2024 | R18: 05/22/2024 | S18: 45434 | T18: PASS | U18: 45434 | V18: May | W18: 2024 | X18: Q2 | Y18: Wednesday | Z18: 6.2h | AA18: 6.2 | AB18: {=_xlfn.LET(_xlpm.x,IFERROR(VALUE(Table2[[#This Row],[Response_Time_Hours]]),""),IF(_xlpm.x="","CHECK",_xlfn.IFS(_xlpm.x<=1,"Immediate",_xlpm.x<=6,"Fast",_xlpm.x<=24,"Moderate",_xlpm.x>24,"Delayed")))} -> Moderate | AC18: 9 | AD18: {=IF(Table2[[#This Row],[Interaction_Count_Final]]="","N/A",_xlfn.IFS(Table2[[#This Row],[Interaction_Count_Final]]<=2,"Low",Table2[[#This Row],[Interaction_Count_Final]]<=5,"Medium",Table2[[#This Row],[Interaction_Count_Final]]>=6,"High",TRUE,"CHECK"))} -> High | AE18: Medium | AF18: TRUE | AG18: TRUE | AH18: 25 | AI18: 45434 | AJ18: TRUE | AK18: {=_xlfn.LET( _xlpm.txt,TRIM(Raw_Data!F18), _xlpm.norm,SUBSTITUTE(SUBSTITUTE(_xlpm.txt,"-","/"),".","/"), _xlpm.p,_xlfn.TEXTSPLIT(_xlpm.norm,"/"), _xlpm.a,VALUE(INDEX(_xlpm.p,1)), _xlpm.b,VALUE(INDEX(_xlpm.p,2)), IF(AND(_xlpm.a<=12,_xlpm.b<=12),"REVIEW_AMBIGUOUS","OK") )} -> OK
A19: CL-0463 | B19: CL-0463 | C19: FALSE | D19: KEEP | E19: Client_463 | F19: Client_463 | G19: A Leading Utility Company | H19: Kuching | I19: Kuching | J19: Kuching | K19: QUALIFIED | L19: QUALIFIED | M19: =IF(UPPER(TRIM(Table2[[#This Row],[Status_Clean]]))="CONVERTED",1,0) -> 0 | N19: =IF(ISNUMBER(MATCH(UPPER(TRIM(Table2[[#This Row],[Status_Clean]])),{"CONTACTED","QUALIFIED","CONVERTED"},0)),1,0) -> 1 | O19: {=_xlfn.SWITCH(UPPER(TRIM(Table2[[#This Row],[Status_Clean]])),"NEW",1,"CONTACTED",2,"QUALIFIED",3,"CONVERTED",4,"LOST",5,99)} -> 3 | P19: 45455 | Q19: 12/06/2024 | R19: 12/06/2024 | S19: 45455 | T19: PASS | U19: 45455 | V19: June | W19: 2024 | X19: Q2 | Y19: Wednesday | Z19: 18.3 | AA19: 18.3 | AB19: {=_xlfn.LET(_xlpm.x,IFERROR(VALUE(Table2[[#This Row],[Response_Time_Hours]]),""),IF(_xlpm.x="","CHECK",_xlfn.IFS(_xlpm.x<=1,"Immediate",_xlpm.x<=6,"Fast",_xlpm.x<=24,"Moderate",_xlpm.x>24,"Delayed")))} -> Moderate | AC19: 48 | AD19: {=IF(Table2[[#This Row],[Interaction_Count_Final]]="","N/A",_xlfn.IFS(Table2[[#This Row],[Interaction_Count_Final]]<=2,"Low",Table2[[#This Row],[Interaction_Count_Final]]<=5,"Medium",Table2[[#This Row],[Interaction_Count_Final]]>=6,"High",TRUE,"CHECK"))} -> High | AE19: Medium | AF19: TRUE | AG19: TRUE | AH19: 26 | AI19: 45455 | AJ19: TRUE | AK19: {=_xlfn.LET( _xlpm.txt,TRIM(Raw_Data!F19), _xlpm.norm,SUBSTITUTE(SUBSTITUTE(_xlpm.txt,"-","/"),".","/"), _xlpm.p,_xlfn.TEXTSPLIT(_xlpm.norm,"/"), _xlpm.a,VALUE(INDEX(_xlpm.p,1)), _xlpm.b,VALUE(INDEX(_xlpm.p,2)), IF(AND(_xlpm.a<=12,_xlpm.b<=12),"REVIEW_AMBIGUOUS","OK") )} -> #REF!
A20: CL-1743 | B20: CL-1743 | C20: FALSE | D20: KEEP | E20: Client_1743 | F20: Client_1743 | G20: A Private Manufacturing Enterprise | H20: Peneng | I20: Peneng | J20: Penang | K20: QUALIFIED | L20: QUALIFIED | M20: =IF(UPPER(TRIM(Table2[[#This Row],[Status_Clean]]))="CONVERTED",1,0) -> 0 | N20: =IF(ISNUMBER(MATCH(UPPER(TRIM(Table2[[#This Row],[Status_Clean]])),{"CONTACTED","QUALIFIED","CONVERTED"},0)),1,0) -> 1 | O20: {=_xlfn.SWITCH(UPPER(TRIM(Table2[[#This Row],[Status_Clean]])),"NEW",1,"CONTACTED",2,"QUALIFIED",3,"CONVERTED",4,"LOST",5,99)} -> 3 | P20: 44938 | Q20: 12/01/2023 | R20: 12/01/2023 | S20: 44938 | T20: PASS | U20: 44938 | V20: January | W20: 2023 | X20: Q1 | Y20: Thursday | Z20: 40.0 hrs | AA20: 40 | AB20: {=_xlfn.LET(_xlpm.x,IFERROR(VALUE(Table2[[#This Row],[Response_Time_Hours]]),""),IF(_xlpm.x="","CHECK",_xlfn.IFS(_xlpm.x<=1,"Immediate",_xlpm.x<=6,"Fast",_xlpm.x<=24,"Moderate",_xlpm.x>24,"Delayed")))} -> Delayed | AC20: 11 | AD20: {=IF(Table2[[#This Row],[Interaction_Count_Final]]="","N/A",_xlfn.IFS(Table2[[#This Row],[Interaction_Count_Final]]<=2,"Low",Table2[[#This Row],[Interaction_Count_Final]]<=5,"Medium",Table2[[#This Row],[Interaction_Count_Final]]>=6,"High",TRUE,"CHECK"))} -> High | AE20: High | AF20: TRUE | AG20: TRUE | AH20: 27 | AI20: 44938 | AJ20: TRUE | AK20: {=_xlfn.LET( _xlpm.txt,TRIM(Raw_Data!F20), _xlpm.norm,SUBSTITUTE(SUBSTITUTE(_xlpm.txt,"-","/"),".","/"), _xlpm.p,_xlfn.TEXTSPLIT(_xlpm.norm,"/"), _xlpm.a,VALUE(INDEX(_xlpm.p,1)), _xlpm.b,VALUE(INDEX(_xlpm.p,2)), IF(AND(_xlpm.a<=12,_xlpm.b<=12),"REVIEW_AMBIGUOUS","OK") )} -> #REF!
A21: CL-0010 | B21: CL-0010 | C21: FALSE | D21: KEEP | E21: Client_010 | F21: Client_010 | G21: A Leading Utility Company | H21: Putrajaya | I21: Putrajaya | J21: Putrajaya | K21: QUALIFEID | L21: QUALIFIED | M21: =IF(UPPER(TRIM(Table2[[#This Row],[Status_Clean]]))="CONVERTED",1,0) -> 0 | N21: =IF(ISNUMBER(MATCH(UPPER(TRIM(Table2[[#This Row],[Status_Clean]])),{"CONTACTED","QUALIFIED","CONVERTED"},0)),1,0) -> 1 | O21: {=_xlfn.SWITCH(UPPER(TRIM(Table2[[#This Row],[Status_Clean]])),"NEW",1,"CONTACTED",2,"QUALIFIED",3,"CONVERTED",4,"LOST",5,99)} -> 3 | P21: September 13, 2024 | Q21: September 13 2024 | R21: September 13 2024 | S21: 45548 | T21: PASS | U21: 45548 | V21: September | W21: 2024 | X21: Q3 | Y21: Friday | Z21: 54 | AA21: 64.7 | AB21: {=_xlfn.LET(_xlpm.x,IFERROR(VALUE(Table2[[#This Row],[Response_Time_Hours]]),""),IF(_xlpm.x="","CHECK",_xlfn.IFS(_xlpm.x<=1,"Immediate",_xlpm.x<=6,"Fast",_xlpm.x<=24,"Moderate",_xlpm.x>24,"Delayed")))} -> Delayed | AC21: 9 | AD21: {=IF(Table2[[#This Row],[Interaction_Count_Final]]="","N/A",_xlfn.IFS(Table2[[#This Row],[Interaction_Count_Final]]<=2,"Low",Table2[[#This Row],[Interaction_Count_Final]]<=5,"Medium",Table2[[#This Row],[Interaction_Count_Final]]>=6,"High",TRUE,"CHECK"))} -> High | AE21: Medium | AF21: TRUE | AG21: TRUE | AH21: 28 | AI21: 45548 | AJ21: TRUE | AK21: {=_xlfn.LET( _xlpm.txt,TRIM(Raw_Data!F21), _xlpm.norm,SUBSTITUTE(SUBSTITUTE(_xlpm.txt,"-","/"),".","/"), _xlpm.p,_xlfn.TEXTSPLIT(_xlpm.norm,"/"), _xlpm.a,VALUE(INDEX(_xlpm.p,1)), _xlpm.b,VALUE(INDEX(_xlpm.p,2)), IF(AND(_xlpm.a<=12,_xlpm.b<=12),"REVIEW_AMBIGUOUS","OK") )} -> #REF!
A22: CL-0162 | B22: CL-0162 | C22: FALSE | D22: KEEP | E22: Client_162 | F22: Client_162 | G22: A Regional Financial Institution | H22: Putrajaya | I22: Putrajaya | J22: Putrajaya | K22: CONVERTED | L22: CONVERTED | M22: =IF(UPPER(TRIM(Table2[[#This Row],[Status_Clean]]))="CONVERTED",1,0) -> 1 | N22: =IF(ISNUMBER(MATCH(UPPER(TRIM(Table2[[#This Row],[Status_Clean]])),{"CONTACTED","QUALIFIED","CONVERTED"},0)),1,0) -> 1 | O22: {=_xlfn.SWITCH(UPPER(TRIM(Table2[[#This Row],[Status_Clean]])),"NEW",1,"CONTACTED",2,"QUALIFIED",3,"CONVERTED",4,"LOST",5,99)} -> 4 | P22: 45573 | Q22: 08/10/2024 | R22: 08/10/2024 | S22: 45573 | T22: PASS | U22: 45573 | V22: October | W22: 2024 | X22: Q4 | Y22: Tuesday | Z22: 51.7h | AA22: 51.7 | AB22: {=_xlfn.LET(_xlpm.x,IFERROR(VALUE(Table2[[#This Row],[Response_Time_Hours]]),""),IF(_xlpm.x="","CHECK",_xlfn.IFS(_xlpm.x<=1,"Immediate",_xlpm.x<=6,"Fast",_xlpm.x<=24,"Moderate",_xlpm.x>24,"Delayed")))} -> Delayed | AC22: 7 | AD22: {=IF(Table2[[#This Row],[Interaction_Count_Final]]="","N/A",_xlfn.IFS(Table2[[#This Row],[Interaction_Count_Final]]<=2,"Low",Table2[[#This Row],[Interaction_Count_Final]]<=5,"Medium",Table2[[#This Row],[Interaction_Count_Final]]>=6,"High",TRUE,"CHECK"))} -> High | AE22: High | AF22: TRUE | AG22: TRUE | AH22: 29 | AI22: 45573 | AJ22: TRUE | AK22: {=_xlfn.LET( _xlpm.txt,TRIM(Raw_Data!F22), _xlpm.norm,SUBSTITUTE(SUBSTITUTE(_xlpm.txt,"-","/"),".","/"), _xlpm.p,_xlfn.TEXTSPLIT(_xlpm.norm,"/"), _xlpm.a,VALUE(INDEX(_xlpm.p,1)), _xlpm.b,VALUE(INDEX(_xlpm.p,2)), IF(AND(_xlpm.a<=12,_xlpm.b<=12),"REVIEW_AMBIGUOUS","OK") )} -> #REF!
A23: CL-0946 | B23: CL-0946 | C23: FALSE | D23: KEEP | E23: Client_946 | F23: Client_946 | G23: A Regional Financial Institution | H23: Kuching | I23: Kuching | J23: Kuching | K23: LOST | L23: LOST | M23: =IF(UPPER(TRIM(Table2[[#This Row],[Status_Clean]]))="CONVERTED",1,0) -> 0 | N23: =IF(ISNUMBER(MATCH(UPPER(TRIM(Table2[[#This Row],[Status_Clean]])),{"CONTACTED","QUALIFIED","CONVERTED"},0)),1,0) -> 0 | O23: {=_xlfn.SWITCH(UPPER(TRIM(Table2[[#This Row],[Status_Clean]])),"NEW",1,"CONTACTED",2,"QUALIFIED",3,"CONVERTED",4,"LOST",5,99)} -> 5 | P23: 01-18-2024 | Q23: 01/18/2024 | R23: 01/18/2024 | S23: 45309 | T23: PASS | U23: 45309 | V23: January | W23: 2024 | X23: Q1 | Y23: Thursday | Z23: 0.8 days | AA23: 19.2 | AB23: {=_xlfn.LET(_xlpm.x,IFERROR(VALUE(Table2[[#This Row],[Response_Time_Hours]]),""),IF(_xlpm.x="","CHECK",_xlfn.IFS(_xlpm.x<=1,"Immediate",_xlpm.x<=6,"Fast",_xlpm.x<=24,"Moderate",_xlpm.x>24,"Delayed")))} -> Moderate | AC23: 8 | AD23: {=IF(Table2[[#This Row],[Interaction_Count_Final]]="","N/A",_xlfn.IFS(Table2[[#This Row],[Interaction_Count_Final]]<=2,"Low",Table2[[#This Row],[Interaction_Count_Final]]<=5,"Medium",Table2[[#This Row],[Interaction_Count_Final]]>=6,"High",TRUE,"CHECK"))} -> High | AE23: Medium | AF23: TRUE | AG23: TRUE | AH23: 30 | AI23: 45309 | AJ23: TRUE | AK23: {=_xlfn.LET( _xlpm.txt,TRIM(Raw_Data!F23), _xlpm.norm,SUBSTITUTE(SUBSTITUTE(_xlpm.txt,"-","/"),".","/"), _xlpm.p,_xlfn.TEXTSPLIT(_xlpm.norm,"/"), _xlpm.a,VALUE(INDEX(_xlpm.p,1)), _xlpm.b,VALUE(INDEX(_xlpm.p,2)), IF(AND(_xlpm.a<=12,_xlpm.b<=12),"REVIEW_AMBIGUOUS","OK") )} -> OK
A24: CL-0661 | B24: CL-0661 | C24: FALSE | D24: KEEP | E24: Client_661 | F24: Client_661 | G24: A Private Manufacturing Enterprise | H24: Klang | I24: Klang | J24: Klang | K24: NEW | L24: NEW | M24: =IF(UPPER(TRIM(Table2[[#This Row],[Status_Clean]]))="CONVERTED",1,0) -> 0 | N24: =IF(ISNUMBER(MATCH(UPPER(TRIM(Table2[[#This Row],[Status_Clean]])),{"CONTACTED","QUALIFIED","CONVERTED"},0)),1,0) -> 0 | O24: {=_xlfn.SWITCH(UPPER(TRIM(Table2[[#This Row],[Status_Clean]])),"NEW",1,"CONTACTED",2,"QUALIFIED",3,"CONVERTED",4,"LOST",5,99)} -> 1 | P24: 45127 | Q24: 20/07/2023 | R24: 20/07/2023 | S24: 45127 | T24: PASS | U24: 45127 | V24: July | W24: 2023 | X24: Q3 | Y24: Thursday | Z24: 48.9 | AA24: 48.9 | AB24: {=_xlfn.LET(_xlpm.x,IFERROR(VALUE(Table2[[#This Row],[Response_Time_Hours]]),""),IF(_xlpm.x="","CHECK",_xlfn.IFS(_xlpm.x<=1,"Immediate",_xlpm.x<=6,"Fast",_xlpm.x<=24,"Moderate",_xlpm.x>24,"Delayed")))} -> Delayed | AC24: 26 | AD24: {=IF(Table2[[#This Row],[Interaction_Count_Final]]="","N/A",_xlfn.IFS(Table2[[#This Row],[Interaction_Count_Final]]<=2,"Low",Table2[[#This Row],[Interaction_Count_Final]]<=5,"Medium",Table2[[#This Row],[Interaction_Count_Final]]>=6,"High",TRUE,"CHECK"))} -> High | AE24: Medium | AF24: TRUE | AG24: TRUE | AH24: 32 | AI24: 45127 | AJ24: TRUE | AK24: {=_xlfn.LET( _xlpm.txt,TRIM(Raw_Data!F24), _xlpm.norm,SUBSTITUTE(SUBSTITUTE(_xlpm.txt,"-","/"),".","/"), _xlpm.p,_xlfn.TEXTSPLIT(_xlpm.norm,"/"), _xlpm.a,VALUE(INDEX(_xlpm.p,1)), _xlpm.b,VALUE(INDEX(_xlpm.p,2)), IF(AND(_xlpm.a<=12,_xlpm.b<=12),"REVIEW_AMBIGUOUS","OK") )} -> #REF!
A25: CL-0650 | B25: CL-0650 | C25: FALSE | D25: KEEP | E25: Client_650 | F25: Client_650 | G25: A Government Service Provider | H25: Kuching | I25: Kuching | J25: Kuching | K25: NEW | L25: NEW | M25: =IF(UPPER(TRIM(Table2[[#This Row],[Status_Clean]]))="CONVERTED",1,0) -> 0 | N25: =IF(ISNUMBER(MATCH(UPPER(TRIM(Table2[[#This Row],[Status_Clean]])),{"CONTACTED","QUALIFIED","CONVERTED"},0)),1,0) -> 0 | O25: {=_xlfn.SWITCH(UPPER(TRIM(Table2[[#This Row],[Status_Clean]])),"NEW",1,"CONTACTED",2,"QUALIFIED",3,"CONVERTED",4,"LOST",5,99)} -> 1 | P25: 10-23-2023 | Q25: 10/23/2023 | R25: 10/23/2023 | S25: 45222 | T25: PASS | U25: 45222 | V25: October | W25: 2023 | X25: Q4 | Y25: Monday | Z25: 8.5 hrs | AA25: 8.5 | AB25: {=_xlfn.LET(_xlpm.x,IFERROR(VALUE(Table2[[#This Row],[Response_Time_Hours]]),""),IF(_xlpm.x="","CHECK",_xlfn.IFS(_xlpm.x<=1,"Immediate",_xlpm.x<=6,"Fast",_xlpm.x<=24,"Moderate",_xlpm.x>24,"Delayed")))} -> Moderate | AC25: 14 | AD25: {=IF(Table2[[#This Row],[Interaction_Count_Final]]="","N/A",_xlfn.IFS(Table2[[#This Row],[Interaction_Count_Final]]<=2,"Low",Table2[[#This Row],[Interaction_Count_Final]]<=5,"Medium",Table2[[#This Row],[Interaction_Count_Final]]>=6,"High",TRUE,"CHECK"))} -> High | AE25: Low | AF25: TRUE | AG25: TRUE | AH25: 33 | AI25: 45222 | AJ25: TRUE | AK25: {=_xlfn.LET( _xlpm.txt,TRIM(Raw_Data!F25), _xlpm.norm,SUBSTITUTE(SUBSTITUTE(_xlpm.txt,"-","/"),".","/"), _xlpm.p,_xlfn.TEXTSPLIT(_xlpm.norm,"/"), _xlpm.a,VALUE(INDEX(_xlpm.p,1)), _xlpm.b,VALUE(INDEX(_xlpm.p,2)), IF(AND(_xlpm.a<=12,_xlpm.b<=12),"REVIEW_AMBIGUOUS","OK") )} -> OK
A26: CL-0822 | B26: CL-0822 | C26: FALSE | D26: KEEP | E26: Client_822 | F26: Client_822 | G26: A Regional Financial Institution | H26: Seremban | I26: Seremban | J26: Seremban | K26: QUALIFIED | L26: QUALIFIED | M26: =IF(UPPER(TRIM(Table2[[#This Row],[Status_Clean]]))="CONVERTED",1,0) -> 0 | N26: =IF(ISNUMBER(MATCH(UPPER(TRIM(Table2[[#This Row],[Status_Clean]])),{"CONTACTED","QUALIFIED","CONVERTED"},0)),1,0) -> 1 | O26: {=_xlfn.SWITCH(UPPER(TRIM(Table2[[#This Row],[Status_Clean]])),"NEW",1,"CONTACTED",2,"QUALIFIED",3,"CONVERTED",4,"LOST",5,99)} -> 3 | P26: 02-16-2024 | Q26: 02/16/2024 | R26: 02/16/2024 | S26: 45338 | T26: PASS | U26: 45338 | V26: February | W26: 2024 | X26: Q1 | Y26: Friday | Z26: 0.7 days | AA26: 16.8 | AB26: {=_xlfn.LET(_xlpm.x,IFERROR(VALUE(Table2[[#This Row],[Response_Time_Hours]]),""),IF(_xlpm.x="","CHECK",_xlfn.IFS(_xlpm.x<=1,"Immediate",_xlpm.x<=6,"Fast",_xlpm.x<=24,"Moderate",_xlpm.x>24,"Delayed")))} -> Moderate | AC26: 40 | AD26: {=IF(Table2[[#This Row],[Interaction_Count_Final]]="","N/A",_xlfn.IFS(Table2[[#This Row],[Interaction_Count_Final]]<=2,"Low",Table2[[#This Row],[Interaction_Count_Final]]<=5,"Medium",Table2[[#This Row],[Interaction_Count_Final]]>=6,"High",TRUE,"CHECK"))} -> High | AE26: Low | AF26: TRUE | AG26: TRUE | AH26: 34 | AI26: 45338 | AJ26: TRUE | AK26: {=_xlfn.LET( _xlpm.txt,TRIM(Raw_Data!F26), _xlpm.norm,SUBSTITUTE(SUBSTITUTE(_xlpm.txt,"-","/"),".","/"), _xlpm.p,_xlfn.TEXTSPLIT(_xlpm.norm,"/"), _xlpm.a,VALUE(INDEX(_xlpm.p,1)), _xlpm.b,VALUE(INDEX(_xlpm.p,2)), IF(AND(_xlpm.a<=12,_xlpm.b<=12),"REVIEW_AMBIGUOUS","OK") )} -> OK
A27: CL-2251 | B27: CL-2251 | C27: FALSE | D27: KEEP | E27: Client_2251 | F27: Client_2251 | G27: A Major Telecommunications Provider | H27: Petaling Jaya | I27: Petaling Jaya | J27: Petaling Jaya | K27: NEW | L27: NEW | M27: =IF(UPPER(TRIM(Table2[[#This Row],[Status_Clean]]))="CONVERTED",1,0) -> 0 | N27: =IF(ISNUMBER(MATCH(UPPER(TRIM(Table2[[#This Row],[Status_Clean]])),{"CONTACTED","QUALIFIED","CONVERTED"},0)),1,0) -> 0 | O27: {=_xlfn.SWITCH(UPPER(TRIM(Table2[[#This Row],[Status_Clean]])),"NEW",1,"CONTACTED",2,"QUALIFIED",3,"CONVERTED",4,"LOST",5,99)} -> 1 | P27: June 17, 2023 | Q27: June 17 2023 | R27: June 17 2023 | S27: 45094 | T27: PASS | U27: 45094 | V27: June | W27: 2023 | X27: Q2 | Y27: Saturday | Z27: 0.1 days | AA27: 2.4 | AB27: {=_xlfn.LET(_xlpm.x,IFERROR(VALUE(Table2[[#This Row],[Response_Time_Hours]]),""),IF(_xlpm.x="","CHECK",_xlfn.IFS(_xlpm.x<=1,"Immediate",_xlpm.x<=6,"Fast",_xlpm.x<=24,"Moderate",_xlpm.x>24,"Delayed")))} -> Fast | AC27: 35 | AD27: {=IF(Table2[[#This Row],[Interaction_Count_Final]]="","N/A",_xlfn.IFS(Table2[[#This Row],[Interaction_Count_Final]]<=2,"Low",Table2[[#This Row],[Interaction_Count_Final]]<=5,"Medium",Table2[[#This Row],[Interaction_Count_Final]]>=6,"High",TRUE,"CHECK"))} -> High | AE27: Low | AF27: TRUE | AG27: TRUE | AH27: 35 | AI27: 45094 | AJ27: TRUE | AK27: {=_xlfn.LET( _xlpm.txt,TRIM(Raw_Data!F27), _xlpm.norm,SUBSTITUTE(SUBSTITUTE(_xlpm.txt,"-","/"),".","/"), _xlpm.p,_xlfn.TEXTSPLIT(_xlpm.norm,"/"), _xlpm.a,VALUE(INDEX(_xlpm.p,1)), _xlpm.b,VALUE(INDEX(_xlpm.p,2)), IF(AND(_xlpm.a<=12,_xlpm.b<=12),"REVIEW_AMBIGUOUS","OK") )} -> #REF!
A28: CL-1572 | B28: CL-1572 | C28: FALSE | D28: KEEP | E28: Client_1572 | F28: Client_1572 | G28: A Leading Utility Company | H28: Kota Kinabalu | I28: Kota Kinabalu | J28: Kota Kinabalu | K28: NEW | L28: NEW | M28: =IF(UPPER(TRIM(Table2[[#This Row],[Status_Clean]]))="CONVERTED",1,0) -> 0 | N28: =IF(ISNUMBER(MATCH(UPPER(TRIM(Table2[[#This Row],[Status_Clean]])),{"CONTACTED","QUALIFIED","CONVERTED"},0)),1,0) -> 0 | O28: {=_xlfn.SWITCH(UPPER(TRIM(Table2[[#This Row],[Status_Clean]])),"NEW",1,"CONTACTED",2,"QUALIFIED",3,"CONVERTED",4,"LOST",5,99)} -> 1 | P28: 09.09.2023 | Q28: 09/09/2023 | R28: 09/09/2023 | S28: 45178 | T28: PASS | U28: 45178 | V28: September | W28: 2023 | X28: Q3 | Y28: Saturday | Z28: 67 | AA28: 67 | AB28: {=_xlfn.LET(_xlpm.x,IFERROR(VALUE(Table2[[#This Row],[Response_Time_Hours]]),""),IF(_xlpm.x="","CHECK",_xlfn.IFS(_xlpm.x<=1,"Immediate",_xlpm.x<=6,"Fast",_xlpm.x<=24,"Moderate",_xlpm.x>24,"Delayed")))} -> Delayed | AC28: 43 | AD28: {=IF(Table2[[#This Row],[Interaction_Count_Final]]="","N/A",_xlfn.IFS(Table2[[#This Row],[Interaction_Count_Final]]<=2,"Low",Table2[[#This Row],[Interaction_Count_Final]]<=5,"Medium",Table2[[#This Row],[Interaction_Count_Final]]>=6,"High",TRUE,"CHECK"))} -> High | AE28: Medium | AF28: TRUE | AG28: TRUE | AH28: 36 | AI28: 45178 | AJ28: TRUE | AK28: {=_xlfn.LET( _xlpm.txt,TRIM(Raw_Data!F28), _xlpm.norm,SUBSTITUTE(SUBSTITUTE(_xlpm.txt,"-","/"),".","/"), _xlpm.p,_xlfn.TEXTSPLIT(_xlpm.norm,"/"), _xlpm.a,VALUE(INDEX(_xlpm.p,1)), _xlpm.b,VALUE(INDEX(_xlpm.p,2)), IF(AND(_xlpm.a<=12,_xlpm.b<=12),"REVIEW_AMBIGUOUS","OK") )} -> REVIEW_AMBIGUOUS
A29: CL-2773 | B29: CL-2773 | C29: FALSE | D29: KEEP | E29: Client_2773 | F29: Client_2773 | G29: A Private Manufacturing Enterprise | H29: Klang | I29: Klang | J29: Klang | K29: LOST | L29: LOST | M29: =IF(UPPER(TRIM(Table2[[#This Row],[Status_Clean]]))="CONVERTED",1,0) -> 0 | N29: =IF(ISNUMBER(MATCH(UPPER(TRIM(Table2[[#This Row],[Status_Clean]])),{"CONTACTED","QUALIFIED","CONVERTED"},0)),1,0) -> 0 | O29: {=_xlfn.SWITCH(UPPER(TRIM(Table2[[#This Row],[Status_Clean]])),"NEW",1,"CONTACTED",2,"QUALIFIED",3,"CONVERTED",4,"LOST",5,99)} -> 5 | P29: 28.09.2024 | Q29: 28/09/2024 | R29: 28/09/2024 | S29: 45563 | T29: PASS | U29: 45563 | V29: September | W29: 2024 | X29: Q3 | Y29: Saturday | Z29: 2.4 hrs | AA29: 2.4 | AB29: {=_xlfn.LET(_xlpm.x,IFERROR(VALUE(Table2[[#This Row],[Response_Time_Hours]]),""),IF(_xlpm.x="","CHECK",_xlfn.IFS(_xlpm.x<=1,"Immediate",_xlpm.x<=6,"Fast",_xlpm.x<=24,"Moderate",_xlpm.x>24,"Delayed")))} -> Fast | AC29: 17 | AD29: {=IF(Table2[[#This Row],[Interaction_Count_Final]]="","N/A",_xlfn.IFS(Table2[[#This Row],[Interaction_Count_Final]]<=2,"Low",Table2[[#This Row],[Interaction_Count_Final]]<=5,"Medium",Table2[[#This Row],[Interaction_Count_Final]]>=6,"High",TRUE,"CHECK"))} -> High | AE29: High | AF29: TRUE | AG29: TRUE | AH29: 39 | AI29: 45563 | AJ29: TRUE | AK29: {=_xlfn.LET( _xlpm.txt,TRIM(Raw_Data!F29), _xlpm.norm,SUBSTITUTE(SUBSTITUTE(_xlpm.txt,"-","/"),".","/"), _xlpm.p,_xlfn.TEXTSPLIT(_xlpm.norm,"/"), _xlpm.a,VALUE(INDEX(_xlpm.p,1)), _xlpm.b,VALUE(INDEX(_xlpm.p,2)), IF(AND(_xlpm.a<=12,_xlpm.b<=12),"REVIEW_AMBIGUOUS","OK") )} -> OK
A30: CL-2897 | B30: CL-2897 | C30: FALSE | D30: KEEP | E30: Client_2897 | F30: Client_2897 | G30: A Regional Financial Institution | H30: Kota Kinabalu | I30: Kota Kinabalu | J30: Kota Kinabalu | K30: CONTACTD | L30: CONTACTED | M30: =IF(UPPER(TRIM(Table2[[#This Row],[Status_Clean]]))="CONVERTED",1,0) -> 0 | N30: =IF(ISNUMBER(MATCH(UPPER(TRIM(Table2[[#This Row],[Status_Clean]])),{"CONTACTED","QUALIFIED","CONVERTED"},0)),1,0) -> 1 | O30: {=_xlfn.SWITCH(UPPER(TRIM(Table2[[#This Row],[Status_Clean]])),"NEW",1,"CONTACTED",2,"QUALIFIED",3,"CONVERTED",4,"LOST",5,99)} -> 2 | P30: 45146 | Q30: 08/08/2023 | R30: 08/08/2023 | S30: 45146 | T30: PASS | U30: 45146 | V30: August | W30: 2023 | X30: Q3 | Y30: Tuesday | Z30: 23.2 hours | AA30: 23.2 | AB30: {=_xlfn.LET(_xlpm.x,IFERROR(VALUE(Table2[[#This Row],[Response_Time_Hours]]),""),IF(_xlpm.x="","CHECK",_xlfn.IFS(_xlpm.x<=1,"Immediate",_xlpm.x<=6,"Fast",_xlpm.x<=24,"Moderate",_xlpm.x>24,"Delayed")))} -> Moderate | AC30: 8 | AD30: {=IF(Table2[[#This Row],[Interaction_Count_Final]]="","N/A",_xlfn.IFS(Table2[[#This Row],[Interaction_Count_Final]]<=2,"Low",Table2[[#This Row],[Interaction_Count_Final]]<=5,"Medium",Table2[[#This Row],[Interaction_Count_Final]]>=6,"High",TRUE,"CHECK"))} -> High | AE30: Medium | AF30: TRUE | AG30: TRUE | AH30: 41 | AI30: 45146 | AJ30: TRUE | AK30: {=_xlfn.LET( _xlpm.txt,TRIM(Raw_Data!F30), _xlpm.norm,SUBSTITUTE(SUBSTITUTE(_xlpm.txt,"-","/"),".","/"), _xlpm.p,_xlfn.TEXTSPLIT(_xlpm.norm,"/"), _xlpm.a,VALUE(INDEX(_xlpm.p,1)), _xlpm.b,VALUE(INDEX(_xlpm.p,2)), IF(AND(_xlpm.a<=12,_xlpm.b<=12),"REVIEW_AMBIGUOUS","OK") )} -> #REF!
A31: CL-2867 | B31: CL-2867 | C31: FALSE | D31: KEEP | E31: Client_2867 | F31: Client_2867 | G31: A Leading Utility Company | H31: Shah Alam | I31: Shah Alam | J31: Shah Alam | K31: CONCTACTED | L31: CONTACTED | M31: =IF(UPPER(TRIM(Table2[[#This Row],[Status_Clean]]))="CONVERTED",1,0) -> 0 | N31: =IF(ISNUMBER(MATCH(UPPER(TRIM(Table2[[#This Row],[Status_Clean]])),{"CONTACTED","QUALIFIED","CONVERTED"},0)),1,0) -> 1 | O31: {=_xlfn.SWITCH(UPPER(TRIM(Table2[[#This Row],[Status_Clean]])),"NEW",1,"CONTACTED",2,"QUALIFIED",3,"CONVERTED",4,"LOST",5,99)} -> 2 | P31: 45481 | Q31: 08/07/2024 | R31: 08/07/2024 | S31: 45481 | T31: PASS | U31: 45481 | V31: July | W31: 2024 | X31: Q3 | Y31: Monday | Z31: 2.3 days | AA31: 55.2 | AB31: {=_xlfn.LET(_xlpm.x,IFERROR(VALUE(Table2[[#This Row],[Response_Time_Hours]]),""),IF(_xlpm.x="","CHECK",_xlfn.IFS(_xlpm.x<=1,"Immediate",_xlpm.x<=6,"Fast",_xlpm.x<=24,"Moderate",_xlpm.x>24,"Delayed")))} -> Delayed | AC31: 22 | AD31: {=IF(Table2[[#This Row],[Interaction_Count_Final]]="","N/A",_xlfn.IFS(Table2[[#This Row],[Interaction_Count_Final]]<=2,"Low",Table2[[#This Row],[Interaction_Count_Final]]<=5,"Medium",Table2[[#This Row],[Interaction_Count_Final]]>=6,"High",TRUE,"CHECK"))} -> High | AE31: High | AF31: TRUE | AG31: TRUE | AH31: 43 | AI31: 45481 | AJ31: TRUE | AK31: {=_xlfn.LET( _xlpm.txt,TRIM(Raw_Data!F31), _xlpm.norm,SUBSTITUTE(SUBSTITUTE(_xlpm.txt,"-","/"),".","/"), _xlpm.p,_xlfn.TEXTSPLIT(_xlpm.norm,"/"), _xlpm.a,VALUE(INDEX(_xlpm.p,1)), _xlpm.b,VALUE(INDEX(_xlpm.p,2)), IF(AND(_xlpm.a<=12,_xlpm.b<=12),"REVIEW_AMBIGUOUS","OK") )} -> #REF!
